Workbook

Sheet Sheet6

Sheet > Données
E5: Données d'entrées

Sheet Sheet1
A1: <PrevHome_AttDef1>
I2: 22 | J2: 11th | K2: 3rd
A3: <PrevHome_AttDef2>
A5: =1-A2 -> 1 | B5: =80-B2 -> 80 | C5: =1-C2 -> 1 | D5: =80-D2 -> 80
A7: <PrevAway_AttDef1>
I8: 22 | J8: 11th | K8: 3rd
A9: <PrevAway_AttDef2>
A11: =1-A8 -> 1 | B11: =80-B8 -> 80 | C11: =1-C8 -> 1 | D11: =80-D8 -> 80
A12: <PrevHomeTries> | E12: <PrevHomePoints> | I12: <PrevAwayTries> | M12: <PrevAwayPoints>
A17: <PrevHomeBallCarry> | E17: <PrevHomeBallCarryM> | I17: <PrevAwayBallCarry> | M17: <PrevAwayBallCarryM>
A22: <PrevHomeLinebreak> | E22: <PrevHomeLinebreak1st> | I22: <PrevAwayLinebreak> | M22: <PrevAwayLinebreak1st>
A27: <PrevHomeTacklebreak> | E27: <PrevHomeOffload> | I27: <PrevAwayTacklebreak> | M27: <PrevAwayOffload>
A32: <PrevHomeTacklesMade> | E32: <PrevHomeTacklesMissed> | I32: <PrevAwayTackle> | M32: <PrevAwayTackleMiss>
A37: <PrevHomeTacklesAttempt> | E37: <PrevHomeTackle%> | H37: =1-G37 -> 1 | I37: <PrevAwayTackleAttempt> | M37: <PrevAwayTackle%> | P37: =1-O37 -> 1
A42: <PrevHomeAssist> | E42: <PrevHomeDominant> | I42: <PrevAwayTackleAssist> | M42: <PrevAwayTackleDom>
A47: <PrevHomeLinebreakCon> | E47: <PrevHomeTackleBreakCon> | I47: <PrevAwayLinebreakCon> | M47: <PrevAwayOffload>
A49: <PrevHomeOffloadCon> | E49: <PrevHomeMetresCon> | I49: <PrevAwayTacklebreak> | M49: <PrevAwayOffload>
A51: <PrevHomePens> | Q51: <PrevAwayPens>
A58: <PrevHomePensTeam> | D58: <PrevHomePensRank> | Q58: <PrevAwayPensTeam> | T58: <PrevAwayPensRank>

Sheet Sheet2
A1: TOTAL | B1: Total Lineouts | C1: Lineouts Won | D1: Lineouts Won % | E1: Lineouts Lost | F1: Lineouts Lost % | G1: Effective Lineouts | H1: Ineffective Lineouts | I1: Lineouts Stolen | J1: Total Scrums | K1: Scrums Won | L1: Scrums Reset | M1: Scrums Won % | N1: Scrums Lost | O1: Scrums Lost %
A2: <PrevBothSet>
B4: TOTAL SCRUMS | H4: OWN SCRUMS | L4: OPPOSITION SCRUMS
A5: TOTAL | B5: Own Scrums | C5: Opp Scrums | D5: Penalties Conceded | E5: Free Kick Conceded | F5: Penalties Won | G5: Free Kicks Won | H5: Penalties Conceded | I5: Free Kick Conceded | J5: Penalties Won | K5: Free Kicks Won | L5: Penalties Conceded | M5: Free Kick Conceded | N5: Penalties Won | O5: Free Kicks Won
A6: <PrevBothScrum>
A9: TOTAL | B9: Total Lineouts | C9: Lineouts Won | D9: Lineouts Won % | E9: Lineouts Lost | F9: Lineouts Lost % | G9: Effective Lineouts | H9: Ineffective Lineouts | I9: Lineouts Stolen | J9: Total Scrums | K9: Scrums Won | L9: Scrums Reset | M9: Scrums Won % | N9: Scrums Lost | O9: Scrums Lost %
A10: <PrevBothSetPieceOpp>
B12: ATTACKING | K12: DEFENDING
A13: TOTAL | B13: Total Lineouts | C13: Lineouts Won | D13: Lineouts Won % | E13: Lineouts Lost | F13: Lineouts Lost % | G13: Effective Lineouts | H13: Effective Lineouts % | I13: Ineffective Lineouts | J13: Ineffective Lineouts % | K13: Total Lineouts | L13: Lineouts Stolen | M13: Lineouts Stolen % | N13: Ineffective Lineouts | O13: Ineffective Lineouts % | P13: Lineouts Lost | Q13: Lineouts Lost %
A14: <PrevBothLineout>
A16: TOTAL | B16: Full E | C16: Full I | D16: Full T | E16: 6E | F16: 6I | G16: 6T | H16: 5E | I16: 5I | J16: 5T | K16: 4E | L16: 4I | M16: 4T | N16: 3E | O16: 3I | P16: 3T | Q16: 2E | R16: 2I | S16: 2T | T16: QE | U16: QI | V16: QT
A17: <PrevBothLineoutForm>
A19: TOTAL | B19: HalfLong | C19: HalfShortWon | D19: HalfShortLost | E19: 22Long | F19: 22ShortWon | G19: 22ShortLost | H19: Short % | I19: Short Won %
A20: <PrevBothRestartLength>
A22: TOTAL | B22: Gainline Made | C22: GainLine Lost | D22: Gainline Made % | E22: Gainline Lost % | F22: CollisionsEffective | G22: Collision Ineffective | H22: Collision Effective %
A23: <PrevBothGainlineOwn>
A25: TOTAL | B25: Gainline Made | C25: GainLine Lost | D25: Gainline Made % | E25: Gainline Lost % | F25: CollisionsEffective | G25: Collision Ineffective | H25: Collision Effective %
A26: <PrevBothGainlineOpp>
A28: TOTAL | B28: Rucks Won % | C28: Rucks Won | D28: Rucks Lost | E28: Att 0-3 | F28: Att 3-6 | G28: Att >6 | H28: Def 0-3 | I28: Def 3-6 | J28: Def 6> | K28: Att 0-3% | L28: Att 3-6% | M28: Att 6P % | N28: Def 0-3% | O28: Def 3-6% | P28: Def 6P% | Q28: Steals
A29: <PrevBothBreakdownPage> | R29: =F29+G29 -> 0 | S29: =E29+G29 -> 0 | T29: =E29+F29 -> 0 | U29: =I29+J29 -> 0 | V29: =H29+J29 -> 0 | W29: =H29+I29 -> 0
R30: =F30+G30 -> 0 | S30: =E30+G30 -> 0 | T30: =E30+F30 -> 0 | U30: =I30+J30 -> 0 | V30: =H30+J30 -> 0 | W30: =H30+I30 -> 0
A32: <PrevHomeBD_AttRuck> | E32: <PrevHomeBD_DefRuck> | J32: <PrevAwayBD_AttRuck> | N32: <PrevAwayBD_DefRuck>
A37: <PrevHomeBD_AttRuck3> | E37: <PrevHomeBD_DefRuck3> | J37: <PrevAwayBD_AttRuck3> | N37: <PrevAwayBD_DefRuck3>
A42: <PrevHomeBD_Clean> | E42: <PrevHomeBD_Steal> | J42: <PrevAwayBD_Clean> | N42: <PrevAwayBD_Steal>

Sheet Sheet3
A1: <SquadHome2>
AL2: =IF(Sheet3!C2<>"",_xlfn.NUMBERVALUE(Sheet3!C2),"") | AM2: =IF(Sheet3!D2<>"",_xlfn.NUMBERVALUE(Sheet3!D2),"") | AN2: =IF(Sheet3!E2<>"",_xlfn.NUMBERVALUE(Sheet3!E2),"") | AO2: =IF(Sheet3!F2<>"",_xlfn.NUMBERVALUE(Sheet3!F2),"") | AP2: =IF(Sheet3!G2<>"",_xlfn.NUMBERVALUE(Sheet3!G2),"") | AQ2: =IF(Sheet3!H2<>"",_xlfn.NUMBERVALUE(Sheet3!H2),"") | AR2: =IF(Sheet3!I2<>"",_xlfn.NUMBERVALUE(Sheet3!I2),"") | AS2: =IF(Sheet3!J2<>"",_xlfn.NUMBERVALUE(Sheet3!J2),"") | ... BP2: =IF(Sheet3!AG2<>"",_xlfn.NUMBERVALUE(Sheet3!AG2),"")

Sheet Sheet4
A1: <SquadAway2>
AL2: =IF(Sheet4!C2<>"",_xlfn.NUMBERVALUE(Sheet4!C2),"") | AM2: =IF(Sheet4!D2<>"",_xlfn.NUMBERVALUE(Sheet4!D2),"") | AN2: =IF(Sheet4!E2<>"",_xlfn.NUMBERVALUE(Sheet4!E2),"") | AO2: =IF(Sheet4!F2<>"",_xlfn.NUMBERVALUE(Sheet4!F2),"") | AP2: =IF(Sheet4!G2<>"",_xlfn.NUMBERVALUE(Sheet4!G2),"") | AQ2: =IF(Sheet4!H2<>"",_xlfn.NUMBERVALUE(Sheet4!H2),"") | AR2: =IF(Sheet4!I2<>"",_xlfn.NUMBERVALUE(Sheet4!I2),"") | AS2: =IF(Sheet4!J2<>"",_xlfn.NUMBERVALUE(Sheet4!J2),"") | ... BP2: =IF(Sheet4!AG2<>"",_xlfn.NUMBERVALUE(Sheet4!AG2),"")

Sheet Nom d'équipes
A1: Alias | B1: EXCEL | C1: Python | D1: Ville | E1: Latitude | F1: Longitude
A2: SU Agen | B2: AGEN | C2: SU Agen | D2: Agen | E2: 44.1878 | F2: 0.6212
A3: ASM Clermont | B3: ASM CLERMONT | C3: ASM Clermont | D3: Clermont-Ferrand | E3: 45.7904 | F3: 3.1065
A4: Aviron Bayonnais | B4: AVIRON BAYONNAIS | C4: Aviron Bayonnais | D4: Bayonne | E4: 43.4965 | F4: -1.4728
A5: CA Brive | B5: BRIVE | C5: CA Brive | D5: Brive-la-Gaillarde | E5: 45.1528 | F5: 1.5140
A6: Castres Olympique | B6: CASTRES OLYMPIQUE | C6: Castres Olympique | D6: Castres | E6: 43.5996 | F6: 2.2472
A7: Stade Rochelais | B7: LA ROCHELLE | C7: Stade Rochelais | D7: La Rochelle | E7: 46.1437 | F7: -1.1623
A8: LOU Rugby | B8: LYON OU | C8: LOU Rugby | D8: Lyon | E8: 45.7238 | F8: 4.8322
A9: Montpellier Hérault Rugby | B9: MONTPELLIER HERAULT | C9: Montpellier Hérault Rugby | D9: Montpellier | E9: 43.5902 | F9: 3.8402
A10: Racing 92 | B10: RACING 92 | C10: Racing 92 | D10: Nanterre | E10: 48.8961 | F10: 2.2355
A11: Section Paloise | B11: SECTION PALOISE | C11: Section Paloise | D11: Pau | E11: 43.3051 | F11: -0.3235
A12: Stade Français Paris | B12: STADE FRANCAIS | C12: Stade Français Paris | D12: Paris | E12: 48.8450 | F12: 2.2530
... A15: Union Bordeaux-Bègles | B15: UNION BORDEAUX | C15: Union Bordeaux-Bègles | D15: Bordeaux | E15: 44.8285 | F15: -0.5891
A16: Oyonnax Rugby | C16: Oyonnax Rugby | D16: Oyonnax | E16: 46.2644 | F16: 5.6517
A17: USA Perpignan | C17: USA Perpignan | D17: Perpignan | E17: 42.7111 | F17: 2.8872
A18: FC Grenoble Rugby | C18: FC Grenoble Rugby | D18: Grenoble | E18: 45.1798 | F18: 5.7410

Sheet Possession_Occupation
C1: Nom d'équipe | D1: Temps Effectif | E1: Possession (Temps Effectif) | F1: Possession % | G1: Occupation (Temps Effectif) | H1: Occupation %
C2: AGEN | D2: 582.01667 | E2: 274.8 | F2: 0.47215143 | G2: 278.58333 | H2: 0.47865181
C3: ASM CLERMONT | D3: 554.85 | E3: 290.11667 | F3: 0.52287405 | G3: 263.48333 | H3: 0.47487309
C4: AVIRON BAYONNAIS | D4: 596.55 | E4: 298.8 | F4: 0.50088006 | G4: 278.78333 | H4: 0.46732601
C5: BRIVE | D5: 571.68333 | E5: 276.5 | F5: 0.48365937 | G5: 251.36667 | H5: 0.43969564
C6: CASTRES OLYMPIQUE | D6: 569.3 | E6: 281.03333 | F6: 0.49364717 | G6: 282.5 | H6: 0.49622343
C7: LA ROCHELLE | D7: 547.66667 | E7: 275.68333 | F7: 0.50337797 | G7: 277.16667 | H7: 0.50608643
C8: LYON OU | D8: 579.55 | E8: 295.1 | F8: 0.50918816 | G8: 311.68333 | H8: 0.53780232
C9: MONTPELLIER HERAULT | D9: 559.11667 | E9: 274.7 | F9: 0.4913107 | G9: 272.4 | H9: 0.48719707
C10: RACING 92 | D10: 583.5 | E10: 296.3 | F10: 0.50779777 | G10: 322.26667 | H10: 0.55229934
C11: SECTION PALOISE | D11: 603.66667 | E11: 291.31667 | F11: 0.48257869 | G11: 303.53333 | H11: 0.50281612
C12: STADE FRANCAIS | D12: 573.21667 | E12: 281.06667 | F12: 0.49033234 | G12: 298.86667 | H12: 0.52138517
C13: TOULON | D13: 566.48333 | E13: 287.48333 | F13: 0.50748772 | G13: 287.25 | H13: 0.50707582
... C15: UNION BORDEAUX | D15: 599.83333 | E15: 315.41667 | F15: 0.52584051 | G15: 305.7 | H15: 0.50964157

Sheet Points Marqués- Période
A1: Nom d'équipe | B1: total | C1: 0-20min | D1: 20-40min | E1: 40-60min | F1: 60-80min
A2: AGEN | B2: 323 | C2: 85 | D2: 99 | E2: 77 | F2: 62
A3: ASM CLERMONT | B3: 423 | C3: 74 | D3: 129 | E3: 118 | F3: 102
A4: AVIRON BAYONNAIS | B4: 327 | C4: 72 | D4: 106 | E4: 73 | F4: 76
A5: BRIVE | B5: 364 | C5: 102 | D5: 114 | E5: 58 | F5: 90
A6: CASTRES OLYMPIQUE | B6: 392 | C6: 84 | D6: 117 | E6: 81 | F6: 110
A7: LA ROCHELLE | B7: 370 | C7: 66 | D7: 123 | E7: 99 | F7: 82
A8: LYON OU | B8: 463 | C8: 111 | D8: 98 | E8: 125 | F8: 129
A9: MONTPELLIER HERAULT | B9: 404 | C9: 89 | D9: 106 | E9: 91 | F9: 118
A10: RACING 92 | B10: 451 | C10: 130 | D10: 135 | E10: 81 | F10: 105
A11: SECTION PALOISE | B11: 334 | C11: 81 | D11: 95 | E11: 73 | F11: 85
A12: STADE FRANCAIS | B12: 328 | C12: 87 | D12: 95 | E12: 79 | F12: 67
A13: TOULON | B13: 396 | C13: 82 | D13: 137 | E13: 114 | F13: 63
... A15: UNION BORDEAUX | B15: 475 | C15: 82 | D15: 165 | E15: 104 | F15: 124

Sheet Points Concédés - Periode
C1: Nom d'équipe | D1: Total | E1: 0-20min | F1: 20-40min | G1: 40-60min | H1: 60-80min
C2: AGEN | D2: 414 | E2: 70 | F2: 143 | G2: 117 | H2: 84
C3: ASM CLERMONT | D3: 415 | E3: 152 | F3: 107 | G3: 80 | H3: 76
C4: AVIRON BAYONNAIS | D4: 409 | E4: 105 | F4: 111 | G4: 101 | H4: 92
C5: BRIVE | D5: 439 | E5: 84 | F5: 152 | G5: 108 | H5: 95
C6: CASTRES OLYMPIQUE | D6: 460 | E6: 113 | F6: 160 | G6: 96 | H6: 91
C7: LA ROCHELLE | D7: 377 | E7: 117 | F7: 72 | G7: 72 | H7: 116
C8: LYON OU | D8: 304 | E8: 86 | F8: 111 | G8: 48 | H8: 59
C9: MONTPELLIER HERAULT | D9: 390 | E9: 76 | F9: 122 | G9: 88 | H9: 104
C10: RACING 92 | D10: 326 | E10: 51 | F10: 117 | G10: 96 | H10: 62
C11: SECTION PALOISE | D11: 414 | E11: 86 | F11: 112 | G11: 107 | H11: 109
C12: STADE FRANCAIS | D12: 488 | E12: 96 | F12: 146 | G12: 115 | H12: 131
C13: TOULON | D13: 334 | E13: 83 | F13: 70 | G13: 84 | H13: 97
... C15: UNION BORDEAUX | D15: 317 | E15: 94 | F15: 76 | G15: 71 | H15: 76

Sheet Essais Marqués - Période
A1: Nom d'équipe | B1: Total | C1: 0-20min | D1: 20-40min | E1: 40-60min | F1: 60-80min
A2: AGEN | B2: 36 | C2: 8 | D2: 10 | E2: 12 | F2: 6
A3: ASM CLERMONT | B3: 39 | C3: 4 | D3: 10 | E3: 15 | F3: 10
A4: AVIRON BAYONNAIS | B4: 27 | C4: 5 | D4: 11 | E4: 6 | F4: 5
A5: BRIVE | B5: 32 | C5: 8 | D5: 11 | E5: 4 | F5: 9
A6: CASTRES OLYMPIQUE | B6: 38 | C6: 7 | D6: 12 | E6: 7 | F6: 12
A7: LA ROCHELLE | B7: 38 | C7: 4 | D7: 14 | E7: 11 | F7: 9
A8: LYON OU | B8: 50 | C8: 12 | D8: 9 | E8: 14 | F8: 15
A9: MONTPELLIER HERAULT | B9: 42 | C9: 7 | D9: 11 | E9: 8 | F9: 16
A10: RACING 92 | B10: 51 | C10: 13 | D10: 16 | E10: 9 | F10: 13
A11: SECTION PALOISE | B11: 31 | C11: 5 | D11: 9 | E11: 7 | F11: 10
A12: STADE FRANCAIS | B12: 30 | C12: 6 | D12: 9 | E12: 6 | F12: 9
A13: TOULON | B13: 37 | C13: 8 | D13: 10 | E13: 13 | F13: 6
... A15: UNION BORDEAUX | B15: 53 | C15: 7 | D15: 19 | E15: 12 | F15: 15

Sheet Essai Concédés - Periode
C1: Nom d'équipe | D1: Total | E1: 0-20min | F1: 20-40min | G1: 40-60min | H1: 60-80min
C2: AGEN | D2: 46 | E2: 5 | F2: 17 | G2: 14 | H2: 10
C3: ASM CLERMONT | D3: 45 | E3: 15 | F3: 13 | G3: 10 | H3: 7
C4: AVIRON BAYONNAIS | D4: 45 | E4: 11 | F4: 10 | G4: 14 | H4: 10
C5: BRIVE | D5: 48 | E5: 8 | F5: 16 | G5: 13 | H5: 11
C6: CASTRES OLYMPIQUE | D6: 43 | E6: 10 | F6: 17 | G6: 9 | H6: 7
C7: LA ROCHELLE | D7: 38 | E7: 9 | F7: 5 | G7: 7 | H7: 17
C8: LYON OU | D8: 27 | E8: 6 | F8: 11 | G8: 3 | H8: 7
C9: MONTPELLIER HERAULT | D9: 37 | E9: 5 | F9: 14 | G9: 8 | H9: 10
C10: RACING 92 | D10: 30 | E10: 6 | F10: 10 | G10: 8 | H10: 6
C11: SECTION PALOISE | D11: 42 | E11: 8 | F11: 11 | G11: 10 | H11: 13
C12: STADE FRANCAIS | D12: 50 | E12: 7 | F12: 15 | G12: 13 | H12: 15
C13: TOULON | D13: 32 | E13: 5 | F13: 6 | G13: 8 | H13: 13
... C15: UNION BORDEAUX | D15: 28 | E15: 9 | F15: 4 | G15: 7 | H15: 8

Sheet Essais Origine
A1: Nom d'équipe | B1: Total | C1: Contre-Attaque | D1: Touche | E1: Mêlée | F1: Turnover | G1: Pénalité | H1: Coup de Pied de Pénalité | I1: Pénalité Jouée Vite | J1: Coup-Franc | K1: Renvoi | L1: Renvoi 22 | M1: Arrêt de Volée
A2: AGEN | B2: 36 | C2: 3 | D2: 9 | E2: 9 | F2: 13 | G2: 0 | H2: 0 | I2: 2 | J2: 0 | K2: 0 | L2: 0 | M2: 0
A3: ASM CLERMONT | B3: 39 | C3: 9 | D3: 20 | E3: 6 | F3: 4 | G3: 0 | H3: 0 | I3: 0 | J3: 0 | K3: 0 | L3: 0 | M3: 0
A4: AVIRON BAYONNAIS | B4: 27 | C4: 5 | D4: 8 | E4: 4 | F4: 9 | G4: 0 | H4: 0 | I4: 0 | J4: 0 | K4: 1 | L4: 0 | M4: 0
A5: BRIVE | B5: 32 | C5: 4 | D5: 9 | E5: 4 | F5: 10 | G5: 0 | H5: 0 | I5: 2 | J5: 2 | K5: 1 | L5: 0 | M5: 0
A6: CASTRES OLYMPIQUE | B6: 38 | C6: 4 | D6: 21 | E6: 5 | F6: 4 | G6: 0 | H6: 0 | I6: 2 | J6: 1 | K6: 1 | L6: 0 | M6: 0
A7: LA ROCHELLE | B7: 38 | C7: 4 | D7: 15 | E7: 11 | F7: 7 | G7: 0 | H7: 0 | I7: 1 | J7: 0 | K7: 0 | L7: 0 | M7: 0
A8: LYON OU | B8: 50 | C8: 10 | D8: 23 | E8: 4 | F8: 8 | G8: 0 | H8: 0 | I8: 3 | J8: 1 | K8: 1 | L8: 0 | M8: 0
A9: MONTPELLIER HERAULT | B9: 42 | C9: 7 | D9: 15 | E9: 5 | F9: 11 | G9: 0 | H9: 0 | I9: 3 | J9: 0 | K9: 0 | L9: 1 | M9: 0
A10: RACING 92 | B10: 51 | C10: 6 | D10: 22 | E10: 9 | F10: 12 | G10: 0 | H10: 0 | I10: 2 | J10: 0 | K10: 0 | L10: 0 | M10: 0
A11: SECTION PALOISE | B11: 31 | C11: 5 | D11: 11 | E11: 6 | F11: 8 | G11: 0 | H11: 0 | I11: 1 | J11: 0 | K11: 0 | L11: 0 | M11: 0
A12: STADE FRANCAIS | B12: 30 | C12: 4 | D12: 11 | E12: 9 | F12: 6 | G12: 0 | H12: 0 | I12: 0 | J12: 0 | K12: 0 | L12: 0 | M12: 0
A13: TOULON | B13: 37 | C13: 7 | D13: 17 | E13: 3 | F13: 8 | G13: 0 | H13: 0 | I13: 2 | J13: 0 | K13: 0 | L13: 0 | M13: 0
... A15: UNION BORDEAUX | B15: 53 | C15: 15 | D15: 14 | E15: 10 | F15: 12 | G15: 0 | H15: 0 | I15: 1 | J15: 0 | K15: 1 | L15: 0 | M15: 0

Sheet Essais Phase
C2: Nom d'équipe | D2: Essais | E2: 1 Phase | F2: 2 Phases | G2: 3 Phases | H2: 4 Phases | I2: 5 Phases | J2: 6 Phases | K2: 7 Phases | L2: 8 Phases | M2: 9 Phases | N2: 10 Phases | O2: 10+ Phases
C3: COUNTER ATTACK | D3: 91 | E3: 30 | F3: 9 | G3: 11 | H3: 8 | I3: 7 | J3: 5 | K3: 1 | L3: 4 | M3: 5 | N3: 2 | O3: 9
C4: FAIR CATCH | D4: 0 | E4: 0 | F4: 0 | G4: 0 | H4: 0 | I4: 0 | J4: 0 | K4: 0 | L4: 0 | M4: 0 | N4: 0 | O4: 0
C5: FREE KICK | D5: 5 | E5: 0 | F5: 0 | G5: 1 | H5: 0 | I5: 0 | J5: 2 | K5: 0 | L5: 0 | M5: 1 | N5: 1 | O5: 0
C6: LINEOUT | D6: 204 | E6: 76 | F6: 21 | G6: 23 | H6: 23 | I6: 13 | J6: 7 | K6: 11 | L6: 8 | M6: 7 | N6: 2 | O6: 13
C7: PENALTY SHOT | D7: 0 | E7: 0 | F7: 0 | G7: 0 | H7: 0 | I7: 0 | J7: 0 | K7: 0 | L7: 0 | M7: 0 | N7: 0 | O7: 0
C8: PENALTY KICK | D8: 0 | E8: 0 | F8: 0 | G8: 0 | H8: 0 | I8: 0 | J8: 0 | K8: 0 | L8: 0 | M8: 0 | N8: 0 | O8: 0
C9: SCRUM | D9: 92 | E9: 40 | F9: 9 | G9: 7 | H9: 9 | I9: 3 | J9: 5 | K9: 0 | L9: 5 | M9: 2 | N9: 2 | O9: 10
C10: START 22 | D10: 1 | E10: 0 | F10: 0 | G10: 0 | H10: 0 | I10: 0 | J10: 0 | K10: 0 | L10: 0 | M10: 1 | N10: 0 | O10: 0
C11: START HALF | D11: 5 | E11: 0 | F11: 1 | G11: 1 | H11: 1 | I11: 0 | J11: 1 | K11: 0 | L11: 0 | M11: 0 | N11: 1 | O11: 0
C12: TAP PENALTY | D12: 20 | E12: 6 | F12: 3 | G12: 4 | H12: 3 | I12: 1 | J12: 1 | K12: 0 | L12: 0 | M12: 0 | N12: 0 | O12: 2
C13: TURNOVER | D13: 123 | E13: 42 | F13: 16 | G13: 9 | H13: 7 | I13: 16 | J13: 7 | K13: 6 | L13: 5 | M13: 5 | N13: 3 | O13: 7

Sheet Essais Phases Equipe
D3: Type de phase | E3: Equipe | F3: Essais | G3: 1 Phase | H3: 2 Phases | I3: 3 Phases | J3: 4 Phases | K3: 5 Phases | L3: 6 Phases | M3: 7 Phases | N3: 8 Phases | O3: 9 Phases | P3: 10 Phases | Q3: 10+ Phases
D4: COUNTER ATTACK | E4: AGEN | F4: 3 | G4: 0 | H4: 0 | I4: 0 | J4: 0 | K4: 1 | L4: 1 | M4: 0 | N4: 1 | O4: 0 | P4: 0 | Q4: 0
D5: FAIR CATCH | E5: AGEN | F5: 0 | G5: 0 | H5: 0 | I5: 0 | J5: 0 | K5: 0 | L5: 0 | M5: 0 | N5: 0 | O5: 0 | P5: 0 | Q5: 0
D6: FREE KICK | E6: AGEN | F6: 0 | G6: 0 | H6: 0 | I6: 0 | J6: 0 | K6: 0 | L6: 0 | M6: 0 | N6: 0 | O6: 0 | P6: 0 | Q6: 0
D7: LINEOUT | E7: AGEN | F7: 9 | G7: 2 | H7: 2 | I7: 1 | J7: 1 | K7: 1 | L7: 0 | M7: 0 | N7: 0 | O7: 0 | P7: 0 | Q7: 2
D8: PENALTY SHOT | E8: AGEN | F8: 0 | G8: 0 | H8: 0 | I8: 0 | J8: 0 | K8: 0 | L8: 0 | M8: 0 | N8: 0 | O8: 0 | P8: 0 | Q8: 0
D9: PENALTY KICK | E9: AGEN | F9: 0 | G9: 0 | H9: 0 | I9: 0 | J9: 0 | K9: 0 | L9: 0 | M9: 0 | N9: 0 | O9: 0 | P9: 0 | Q9: 0
D10: SCRUM | E10: AGEN | F10: 9 | G10: 6 | H10: 0 | I10: 0 | J10: 0 | K10: 0 | L10: 0 | M10: 0 | N10: 2 | O10: 0 | P10: 1 | Q10: 0
D11: START 22 | E11: AGEN | F11: 0 | G11: 0 | H11: 0 | I11: 0 | J11: 0 | K11: 0 | L11: 0 | M11: 0 | N11: 0 | O11: 0 | P11: 0 | Q11: 0
D12: START HALF | E12: AGEN | F12: 0 | G12: 0 | H12: 0 | I12: 0 | J12: 0 | K12: 0 | L12: 0 | M12: 0 | N12: 0 | O12: 0 | P12: 0 | Q12: 0
D13: TAP PENALTY | E13: AGEN | F13: 2 | G13: 1 | H13: 1 | I13: 0 | J13: 0 | K13: 0 | L13: 0 | M13: 0 | N13: 0 | O13: 0 | P13: 0 | Q13: 0
D14: TURNOVER | E14: AGEN | F14: 13 | G14: 5 | H14: 2 | I14: 0 | J14: 2 | K14: 3 | L14: 0 | M14: 0 | N14: 0 | O14: 0 | P14: 1 | Q14: 0
D15: COUNTER ATTACK | E15: ASM CLERMONT | F15: 9 | G15: 1 | H15: 2 | I15: 1 | J15: 1 | K15: 0 | L15: 0 | M15: 1 | N15: 1 | O15: 0 | P15: 0 | Q15: 2
... D158: TURNOVER | E158: UNION BORDEAUX | F158: 12 | G158: 1 | H158: 2 | I158: 2 | J158: 0 | K158: 2 | L158: 1 | M158: 3 | N158: 1 | O158: 0 | P158: 0 | Q158: 0

Sheet Conquête
C1: Nom d'équipe | D1: Total Touches | E1: Touches Gagnées | F1: Touches Gagnées % | G1: Touches Perdues | H1: Touches Perdues % | I1: Touches Efficaces | J1: Touches Inefficaces | K1: Touches Volées | L1: Total Mêlées | M1: Mêlées Gagnées | N1: Mêlées Rejouées | O1: Mêlées Gagnées % | P1: Mêlées Perdues | Q1: Mêlées Perdues %
C2: AGEN | D2: 195 | E2: 171 | F2: 0.87692308 | G2: 24 | H2: 0.12307692 | I2: 152 | J2: 19 | K2: 58 | L2: 179 | M2: 108 | N2: 42 | O2: 0.78832117 | P2: 29 | Q2: 0.21167883
C3: ASM CLERMONT | D3: 231 | E3: 199 | F3: 0.86147186 | G3: 32 | H3: 0.13852814 | I3: 178 | J3: 21 | K3: 32 | L3: 155 | M3: 101 | N3: 39 | O3: 0.87068966 | P3: 15 | Q3: 0.12931034
C4: AVIRON BAYONNAIS | D4: 218 | E4: 188 | F4: 0.86238532 | G4: 30 | H4: 0.13761468 | I4: 172 | J4: 16 | K4: 26 | L4: 129 | M4: 86 | N4: 31 | O4: 0.87755102 | P4: 12 | Q4: 0.12244898
C5: BRIVE | D5: 204 | E5: 156 | F5: 0.76470588 | G5: 48 | H5: 0.23529412 | I5: 128 | J5: 28 | K5: 40 | L5: 143 | M5: 90 | N5: 38 | O5: 0.85714286 | P5: 15 | Q5: 0.14285714
C6: CASTRES OLYMPIQUE | D6: 195 | E6: 162 | F6: 0.83076923 | G6: 33 | H6: 0.16923077 | I6: 143 | J6: 19 | K6: 32 | L6: 132 | M6: 76 | N6: 35 | O6: 0.78350515 | P6: 21 | Q6: 0.21649485
C7: LA ROCHELLE | D7: 219 | E7: 172 | F7: 0.78538813 | G7: 47 | H7: 0.21461187 | I7: 151 | J7: 21 | K7: 28 | L7: 164 | M7: 112 | N7: 39 | O7: 0.896 | P7: 13 | Q7: 0.104
C8: LYON OU | D8: 236 | E8: 195 | F8: 0.82627119 | G8: 41 | H8: 0.17372881 | I8: 181 | J8: 14 | K8: 34 | L8: 127 | M8: 85 | N8: 31 | O8: 0.88541667 | P8: 11 | Q8: 0.11458333
C9: MONTPELLIER HERAULT | D9: 195 | E9: 168 | F9: 0.86153846 | G9: 27 | H9: 0.13846154 | I9: 156 | J9: 12 | K9: 34 | L9: 150 | M9: 88 | N9: 48 | O9: 0.8627451 | P9: 14 | Q9: 0.1372549
C10: RACING 92 | D10: 216 | E10: 189 | F10: 0.875 | G10: 27 | H10: 0.125 | I10: 166 | J10: 23 | K10: 55 | L10: 136 | M10: 101 | N10: 23 | O10: 0.89380531 | P10: 12 | Q10: 0.10619469
C11: SECTION PALOISE | D11: 222 | E11: 165 | F11: 0.74324324 | G11: 57 | H11: 0.25675676 | I11: 147 | J11: 18 | K11: 27 | L11: 160 | M11: 100 | N11: 45 | O11: 0.86956522 | P11: 15 | Q11: 0.13043478
C12: STADE FRANCAIS | D12: 202 | E12: 168 | F12: 0.83168317 | G12: 34 | H12: 0.16831683 | I12: 145 | J12: 23 | K12: 31 | L12: 142 | M12: 89 | N12: 40 | O12: 0.87254902 | P12: 13 | Q12: 0.12745098
C13: TOULON | D13: 240 | E13: 202 | F13: 0.84166667 | G13: 38 | H13: 0.15833333 | I13: 177 | J13: 25 | K13: 33 | L13: 161 | M13: 113 | N13: 41 | O13: 0.94166667 | P13: 7 | Q13: 0.058333333
... C15: UNION BORDEAUX | D15: 194 | E15: 151 | F15: 0.77835052 | G15: 43 | H15: 0.22164948 | I15: 136 | J15: 15 | K15: 59 | L15: 175 | M15: 116 | N15: 45 | O15: 0.89230769 | P15: 14 | Q15: 0.10769231

Sheet Mêlée
C1: Equipe | D1: Mêlées Equipe | E1: Mêlées Adverses | F1: Pénalités Concédées | G1: Coup-Franc Concédés | H1: Pénalités Gagnées | I1: Coup-Franc Gagnés
C2: AGEN | D2: 179 | E2: 155 | F2: 42 | G2: 18 | H2: 19 | I2: 14
C3: ASM CLERMONT | D3: 155 | E3: 152 | F3: 33 | G3: 9 | H3: 40 | I3: 11
C4: AVIRON BAYONNAIS | D4: 129 | E4: 155 | F4: 37 | G4: 8 | H4: 28 | I4: 10
C5: BRIVE | D5: 143 | E5: 173 | F5: 37 | G5: 11 | H5: 35 | I5: 11
C6: CASTRES OLYMPIQUE | D6: 132 | E6: 130 | F6: 39 | G6: 12 | H6: 20 | I6: 12
C7: LA ROCHELLE | D7: 164 | E7: 171 | F7: 47 | G7: 9 | H7: 24 | I7: 8
C8: LYON OU | D8: 127 | E8: 165 | F8: 33 | G8: 13 | H8: 47 | I8: 12
C9: MONTPELLIER HERAULT | D9: 150 | E9: 175 | F9: 43 | G9: 9 | H9: 27 | I9: 12
C10: RACING 92 | D10: 136 | E10: 159 | F10: 30 | G10: 11 | H10: 44 | I10: 8
C11: SECTION PALOISE | D11: 160 | E11: 144 | F11: 28 | G11: 6 | H11: 40 | I11: 5
C12: STADE FRANCAIS | D12: 142 | E12: 143 | F12: 36 | G12: 8 | H12: 38 | I12: 8
C13: TOULON | D13: 161 | E13: 151 | F13: 21 | G13: 12 | H13: 58 | I13: 13
... C15: UNION BORDEAUX | D15: 175 | E15: 117 | F15: 31 | G15: 9 | H15: 32 | I15: 14

Sheet Touche - Attaque
A1: Equipe | B1: Total Touches | C1: Touches Gagnées | D1: Touches Gagnées % | E1: Touches Perdues | F1: Touches Perdues % | G1: Touches Efficaces | H1: Touches Efficaces % | I1: Touches Inefficaces | J1: Touches Inefficaces %
A2: AGEN | B2: 195 | C2: 171 | D2: 0.87692308 | E2: 24 | F2: 0.12307692 | G2: 152 | H2: 0.77948718 | I2: 19 | J2: 0.097435897
A3: ASM CLERMONT | B3: 231 | C3: 199 | D3: 0.86147186 | E3: 32 | F3: 0.13852814 | G3: 178 | H3: 0.77056277 | I3: 21 | J3: 0.090909091
A4: AVIRON BAYONNAIS | B4: 218 | C4: 188 | D4: 0.86238532 | E4: 30 | F4: 0.13761468 | G4: 172 | H4: 0.78899083 | I4: 16 | J4: 0.073394495
A5: BRIVE | B5: 204 | C5: 156 | D5: 0.76470588 | E5: 48 | F5: 0.23529412 | G5: 128 | H5: 0.62745098 | I5: 28 | J5: 0.1372549
A6: CASTRES OLYMPIQUE | B6: 195 | C6: 162 | D6: 0.83076923 | E6: 33 | F6: 0.16923077 | G6: 143 | H6: 0.73333333 | I6: 19 | J6: 0.097435897
A7: LA ROCHELLE | B7: 219 | C7: 172 | D7: 0.78538813 | E7: 47 | F7: 0.21461187 | G7: 151 | H7: 0.68949772 | I7: 21 | J7: 0.095890411
A8: LYON OU | B8: 236 | C8: 195 | D8: 0.82627119 | E8: 41 | F8: 0.17372881 | G8: 181 | H8: 0.76694915 | I8: 14 | J8: 0.059322034
A9: MONTPELLIER HERAULT | B9: 195 | C9: 168 | D9: 0.86153846 | E9: 27 | F9: 0.13846154 | G9: 156 | H9: 0.8 | I9: 12 | J9: 0.061538462
A10: RACING 92 | B10: 216 | C10: 189 | D10: 0.875 | E10: 27 | F10: 0.125 | G10: 166 | H10: 0.76851852 | I10: 23 | J10: 0.10648148
A11: SECTION PALOISE | B11: 222 | C11: 165 | D11: 0.74324324 | E11: 57 | F11: 0.25675676 | G11: 147 | H11: 0.66216216 | I11: 18 | J11: 0.081081081
A12: STADE FRANCAIS | B12: 202 | C12: 168 | D12: 0.83168317 | E12: 34 | F12: 0.16831683 | G12: 145 | H12: 0.71782178 | I12: 23 | J12: 0.11386139
A13: TOULON | B13: 240 | C13: 202 | D13: 0.84166667 | E13: 38 | F13: 0.15833333 | G13: 177 | H13: 0.7375 | I13: 25 | J13: 0.10416667
... A15: UNION BORDEAUX | B15: 194 | C15: 151 | D15: 0.77835052 | E15: 43 | F15: 0.22164948 | G15: 136 | H15: 0.70103093 | I15: 15 | J15: 0.077319588

Sheet Touche
C1: Equipe | D1: Total Touches | E1: Touches Volées | F1: Touches Volées % | G1: Touches Inefficaces | H1: Touches Inefficaces % | I1: Touches Perdues | J1: Touches Perdues %
C2: AGEN | D2: 226 | E2: 58 | F2: 0.25663717 | G2: 26 | H2: 0.11504425 | I2: 142 | J2: 0.62831858
C3: ASM CLERMONT | D3: 204 | E3: 32 | F3: 0.15686275 | G3: 20 | H3: 0.098039216 | I3: 152 | J3: 0.74509804
C4: AVIRON BAYONNAIS | D4: 215 | E4: 26 | F4: 0.12093023 | G4: 15 | H4: 0.069767442 | I4: 174 | J4: 0.80930233
C5: BRIVE | D5: 210 | E5: 40 | F5: 0.19047619 | G5: 15 | H5: 0.071428571 | I5: 155 | J5: 0.73809524
C6: CASTRES OLYMPIQUE | D6: 186 | E6: 32 | F6: 0.17204301 | G6: 16 | H6: 0.086021505 | I6: 138 | J6: 0.74193548
C7: LA ROCHELLE | D7: 233 | E7: 28 | F7: 0.12017167 | G7: 13 | H7: 0.055793991 | I7: 192 | J7: 0.82403433
C8: LYON OU | D8: 218 | E8: 34 | F8: 0.1559633 | G8: 24 | H8: 0.11009174 | I8: 160 | J8: 0.73394495
C9: MONTPELLIER HERAULT | D9: 200 | E9: 34 | F9: 0.17 | G9: 15 | H9: 0.075 | I9: 151 | J9: 0.755
C10: RACING 92 | D10: 226 | E10: 55 | F10: 0.24336283 | G10: 27 | H10: 0.11946903 | I10: 144 | J10: 0.63716814
C11: SECTION PALOISE | D11: 215 | E11: 27 | F11: 0.1255814 | G11: 23 | H11: 0.10697674 | I11: 165 | J11: 0.76744186
C12: STADE FRANCAIS | D12: 220 | E12: 31 | F12: 0.14090909 | G12: 16 | H12: 0.072727273 | I12: 173 | J12: 0.78636364
C13: TOULON | D13: 197 | E13: 33 | F13: 0.16751269 | G13: 18 | H13: 0.091370558 | I13: 146 | J13: 0.74111675
... C15: UNION BORDEAUX | D15: 232 | E15: 59 | F15: 0.25431034 | G15: 27 | H15: 0.11637931 | I15: 146 | J15: 0.62931034

Sheet Renvois - 22
A1: Equipe | B1: Tapé Conservé | C1: Tapé Perdu | D1: Reçu (adv) Gagné | E1: Reçu (adv) Perdu
A2: FRENCH TOP 14 | B2: 33 | C2: 183 | D2: 183 | E2: 33
A3: AGEN | B3: 0 | C3: 22 | D3: 18 | E3: 0
A4: ASM CLERMONT | B4: 4 | C4: 10 | D4: 11 | E4: 3
A5: AVIRON BAYONNAIS | B5: 1 | C5: 14 | D5: 19 | E5: 3
A6: BRIVE | B6: 0 | C6: 11 | D6: 8 | E6: 1
A7: CASTRES OLYMPIQUE | B7: 5 | C7: 14 | D7: 14 | E7: 3
A8: LA ROCHELLE | B8: 2 | C8: 12 | D8: 10 | E8: 2
A9: LYON OU | B9: 3 | C9: 12 | D9: 11 | E9: 2
A10: MONTPELLIER HERAULT | B10: 4 | C10: 24 | D10: 13 | E10: 3
A11: RACING 92 | B11: 8 | C11: 6 | D11: 15 | E11: 0
A12: SECTION PALOISE | B12: 3 | C12: 9 | D12: 12 | E12: 0
A13: STADE FRANCAIS | B13: 1 | C13: 7 | D13: 18 | E13: 3
... A16: UNION BORDEAUX | B16: 1 | C16: 9 | D16: 13 | E16: 4

Sheet Renvois
C1: Equipe | D1: Tapé Conservé | E1: Tapé Perdu | F1: Reçu (adv) Gagné | G1: Reçu (adv) Perdu
C2: AGEN | D2: 8 | E2: 88 | F2: 74 | G2: 4
C3: ASM CLERMONT | D3: 18 | E3: 77 | F3: 100 | G3: 8
C4: AVIRON BAYONNAIS | D4: 16 | E4: 80 | F4: 89 | G4: 2
C5: BRIVE | D5: 8 | E5: 91 | F5: 90 | G5: 5
C6: CASTRES OLYMPIQUE | D6: 11 | E6: 99 | F6: 86 | G6: 11
C7: LA ROCHELLE | D7: 4 | E7: 91 | F7: 81 | G7: 12
C8: LYON OU | D8: 9 | E8: 72 | F8: 101 | G8: 6
C9: MONTPELLIER HERAULT | D9: 4 | E9: 96 | F9: 84 | G9: 13
C10: RACING 92 | D10: 5 | E10: 81 | F10: 92 | G10: 8
C11: SECTION PALOISE | D11: 6 | E11: 95 | F11: 74 | G11: 12
C12: STADE FRANCAIS | D12: 8 | E12: 104 | F12: 77 | G12: 6
C13: TOULON | D13: 6 | E13: 80 | F13: 88 | G13: 11
... C15: UNION BORDEAUX | D15: 3 | E15: 85 | F15: 99 | G15: 4

Sheet Tirs au But
C1: TOTAL | D1: Réussis % (Sauf Drops) | E1: Transformations Réussies % | F1: Transformations Réussies | G1: Transformations Manquées | H1: Pénalités Réussies % | I1: Pénalités Réussies | J1: Pénalités Manquées | K1: Drops Réussis % | L1: Drops Réussis | M1: Drops Manqués
C2: AGEN | D2: 0.72 | E2: 0.68571429 | F2: 24 | G2: 11 | H2: 0.75 | I2: 30 | J2: 10 | K2: 0.2 | L2: 1 | M2: 4
C3: ASM CLERMONT | D3: 0.81730769 | E3: 0.76315789 | F3: 29 | G3: 9 | H3: 0.84848485 | I3: 56 | J3: 10 | K3: 0 | L3: 0 | M3: 1
C4: AVIRON BAYONNAIS | D4: 0.74468085 | E4: 0.76923077 | F4: 20 | G4: 6 | H4: 0.73529412 | I4: 50 | J4: 18 | K4: 0 | L4: 0 | M4: 2
C5: BRIVE | D5: 0.89655172 | E5: 0.9375 | F5: 30 | G5: 2 | H5: 0.87272727 | I5: 48 | J5: 7 | K5: 0 | L5: 0 | M5: 1
C6: CASTRES OLYMPIQUE | D6: 0.79569892 | E6: 0.75675676 | F6: 28 | G6: 9 | H6: 0.82142857 | I6: 46 | J6: 10 | K6: 0.66666667 | L6: 2 | M6: 1
C7: LA ROCHELLE | D7: 0.7752809 | E7: 0.78378378 | F7: 29 | G7: 8 | H7: 0.76923077 | I7: 40 | J7: 12 | K7: 0 | L7: 0 | M7: 2
C8: LYON OU | D8: 0.83838384 | E8: 0.78 | F8: 39 | G8: 11 | H8: 0.89795918 | I8: 44 | J8: 5 | K8: 0.5 | L8: 1 | M8: 1
C9: MONTPELLIER HERAULT | D9: 0.8 | E9: 0.80952381 | F9: 34 | G9: 8 | H9: 0.79245283 | I9: 42 | J9: 11 | K9: - | L9: 0 | M9: 0
C10: RACING 92 | D10: 0.75 | E10: 0.74509804 | F10: 38 | G10: 13 | H10: 0.75471698 | I10: 40 | J10: 13 | K10: - | L10: 0 | M10: 0
C11: SECTION PALOISE | D11: 0.79761905 | E11: 0.8 | F11: 24 | G11: 6 | H11: 0.7962963 | I11: 43 | J11: 11 | K11: - | L11: 0 | M11: 0
C12: STADE FRANCAIS | D12: 0.70652174 | E12: 0.75862069 | F12: 22 | G12: 7 | H12: 0.68253968 | I12: 43 | J12: 20 | K12: 0.2 | L12: 1 | M12: 4
C13: TOULON | D13: 0.84615385 | E13: 0.84848485 | F13: 28 | G13: 5 | H13: 0.84482759 | I13: 49 | J13: 9 | K13: 0 | L13: 0 | M13: 1
C14: TOULOUSE | D14: 0.79518072 | E14: 0.70588235 | F14: 24 | G14: 10 | H14: 0.85714286 | I14: 42 | J14: 7 | K14: 0.33333333 | L14: 1 | M14: 2
C15: UNION BORDEAUX | D15: 0.8 | E15: 0.90196078 | F15: 46 | G15: 5 | H15: 0.7037037 | I15: 38 | J15: 16 | K15: - | L15: 0 | M15: 0

Sheet Jeu Courant
B1: Equipe | C1: Essais | D1: Essais de Pénalité | E1: Courses | F1: Mètres Parcourus | G1: Collisions | H1: Passes | I1: Passes - Offloads | J1: Passes Manquées | K1: Franch. | L1: Plaquages Cassés | M1: Jeu au Pied | N1: Mètres au Pied | O1: Erreurs au Pied | P1: Pied Long | Q1: Pied Court | R1: Turnovers | S1: Turnovers Gagnés
B2: AGEN | C2: 36 | D2: 1 | E2: 1742 | F2: 9592 | G2: 1585 | H2: 1900 | I2: 152 | J2: 129 | K2: 56 | L2: 55 | M2: 354 | N2: 10351 | O2: 11 | P2: 232 | Q2: 122 | R2: 211 | S2: 69
B3: ASM CLERMONT | C3: 39 | D3: 1 | E3: 1782 | F3: 11232 | G3: 1635 | H3: 2035 | I3: 96 | J3: 113 | K3: 66 | L3: 95 | M3: 302 | N3: 8331 | O3: 4 | P3: 179 | Q3: 123 | R3: 247 | S3: 55
B4: AVIRON BAYONNAIS | C4: 27 | D4: 1 | E4: 1860 | F4: 10135 | G4: 1736 | H4: 1648 | I4: 181 | J4: 132 | K4: 50 | L4: 98 | M4: 340 | N4: 10103 | O4: 6 | P4: 223 | Q4: 117 | R4: 224 | S4: 57
B5: BRIVE | C5: 32 | D5: 0 | E5: 1708 | F5: 10427 | G5: 1558 | H5: 1716 | I5: 110 | J5: 100 | K5: 57 | L5: 94 | M5: 306 | N5: 8967 | O5: 3 | P5: 217 | Q5: 89 | R5: 233 | S5: 67
B6: CASTRES OLYMPIQUE | C6: 38 | D6: 1 | E6: 1709 | F6: 9724 | G6: 1578 | H6: 1664 | I6: 161 | J6: 131 | K6: 63 | L6: 70 | M6: 334 | N6: 9938 | O6: 13 | P6: 197 | Q6: 137 | R6: 213 | S6: 64
B7: LA ROCHELLE | C7: 38 | D7: 1 | E7: 1778 | F7: 11174 | G7: 1634 | H7: 2154 | I7: 162 | J7: 150 | K7: 62 | L7: 72 | M7: 313 | N7: 8945 | O7: 7 | P7: 206 | Q7: 108 | R7: 234 | S7: 55
B8: LYON OU | C8: 50 | D8: 0 | E8: 1878 | F8: 11308 | G8: 1699 | H8: 1932 | I8: 224 | J8: 154 | K8: 78 | L8: 128 | M8: 370 | N8: 11102 | O8: 9 | P8: 229 | Q8: 141 | R8: 239 | S8: 69
B9: MONTPELLIER HERAULT | C9: 42 | D9: 0 | E9: 1721 | F9: 11155 | G9: 1588 | H9: 1875 | I9: 188 | J9: 122 | K9: 71 | L9: 90 | M9: 298 | N9: 9336 | O9: 6 | P9: 195 | Q9: 105 | R9: 227 | S9: 54
B10: RACING 92 | C10: 51 | D10: 0 | E10: 1847 | F10: 11568 | G10: 1640 | H10: 2134 | I10: 106 | J10: 152 | K10: 70 | L10: 97 | M10: 389 | N10: 10388 | O10: 7 | P10: 228 | Q10: 161 | R10: 225 | S10: 75
B11: SECTION PALOISE | C11: 31 | D11: 1 | E11: 1906 | F11: 11041 | G11: 1776 | H11: 1937 | I11: 151 | J11: 121 | K11: 67 | L11: 76 | M11: 308 | N11: 8871 | O11: 7 | P11: 208 | Q11: 100 | R11: 251 | S11: 49
B12: STADE FRANCAIS | C12: 30 | D12: 1 | E12: 1717 | F12: 10285 | G12: 1602 | H12: 1845 | I12: 132 | J12: 97 | K12: 62 | L12: 90 | M12: 304 | N12: 8906 | O12: 7 | P12: 195 | Q12: 109 | R12: 222 | S12: 79
B13: TOULON | C13: 37 | D13: 4 | E13: 1646 | F13: 10836 | G13: 1519 | H13: 1787 | I13: 143 | J13: 110 | K13: 65 | L13: 129 | M13: 314 | N13: 9008 | O13: 7 | P13: 191 | Q13: 123 | R13: 237 | S13: 49
... B15: UNION BORDEAUX | C15: 53 | D15: 2 | E15: 1996 | F15: 13016 | G15: 1784 | H15: 2091 | I15: 162 | J15: 113 | K15: 93 | L15: 114 | M15: 357 | N15: 10675 | O15: 9 | P15: 228 | Q15: 129 | R15: 218 | S15: 62

Sheet Defence
C3: Equipe | D3: Plaquages Total | E3: Plaquages Réussis % | F3: Plaquages Réussis | G3: Plaquages Offensifs | H3: Plaquages Manqués | I3: Essais Concédés
C4: AGEN | D4: 3080 | E4: 0.88701299 | F4: 2732 | G4: 241 | H4: 348 | I4: 46
C5: ASM CLERMONT | D5: 2336 | E5: 0.88142123 | F5: 2059 | G5: 207 | H5: 277 | I5: 45
C6: AVIRON BAYONNAIS | D6: 2762 | E6: 0.89319334 | F6: 2467 | G6: 127 | H6: 295 | I6: 45
C7: BRIVE | D7: 3055 | E7: 0.87332242 | F7: 2668 | G7: 216 | H7: 387 | I7: 48
C8: CASTRES OLYMPIQUE | D8: 2860 | E8: 0.87762238 | F8: 2510 | G8: 231 | H8: 350 | I8: 43
C9: LA ROCHELLE | D9: 2381 | E9: 0.89122218 | F9: 2122 | G9: 250 | H9: 259 | I9: 38
C10: LYON OU | D10: 2569 | E10: 0.89412223 | F10: 2297 | G10: 207 | H10: 272 | I10: 27
C11: MONTPELLIER HERAULT | D11: 2579 | E11: 0.89685925 | F11: 2313 | G11: 227 | H11: 266 | I11: 37
C12: RACING 92 | D12: 2819 | E12: 0.89286981 | F12: 2517 | G12: 274 | H12: 302 | I12: 30
C13: SECTION PALOISE | D13: 2905 | E13: 0.88846816 | F13: 2581 | G13: 215 | H13: 324 | I13: 42
C14: STADE FRANCAIS | D14: 2839 | E14: 0.89785136 | F14: 2549 | G14: 319 | H14: 290 | I14: 50
C15: TOULON | D15: 2728 | E15: 0.88159824 | F15: 2405 | G15: 287 | H15: 323 | I15: 32
... C17: UNION BORDEAUX | D17: 2706 | E17: 0.89467849 | F17: 2421 | G17: 258 | H17: 285 | I17: 28

Sheet Fautes
C1: Equipe | D1: Pénalités Concédées | E1: Pénalités Obtenues | F1: Jeu Dangereux | G1: Touche | H1: Maul | I1: Hors-Jeu | J1: Ruck | K1: Mêlée | L1: Plaquage | M1: Autre | N1: Jeu Courant | O1: Cartons Jaunes | P1: Cartons Rouges
C2: AGEN | D2: 165 | E2: 133 | F2: 26 | G2: 1 | H2: 14 | I2: 20 | J2: 8 | K2: 41 | L2: 49 | M2: 0 | N2: 6 | O2: 12 | P2: 0
C3: ASM CLERMONT | D3: 157 | E3: 206 | F3: 24 | G3: 1 | H3: 9 | I3: 20 | J3: 15 | K3: 33 | L3: 50 | M3: 0 | N3: 5 | O3: 15 | P3: 1
C4: AVIRON BAYONNAIS | D4: 157 | E4: 192 | F4: 21 | G4: 0 | H4: 11 | I4: 19 | J4: 14 | K4: 36 | L4: 49 | M4: 0 | N4: 7 | O4: 8 | P4: 3
C5: BRIVE | D5: 164 | E5: 157 | F5: 29 | G5: 3 | H5: 13 | I5: 25 | J5: 10 | K5: 35 | L5: 45 | M5: 0 | N5: 4 | O5: 8 | P5: 2
C6: CASTRES OLYMPIQUE | D6: 200 | E6: 156 | F6: 33 | G6: 3 | H6: 18 | I6: 28 | J6: 17 | K6: 39 | L6: 55 | M6: 1 | N6: 6 | O6: 17 | P6: 2
C7: LA ROCHELLE | D7: 183 | E7: 159 | F7: 29 | G7: 4 | H7: 24 | I7: 28 | J7: 7 | K7: 44 | L7: 41 | M7: 0 | N7: 6 | O7: 9 | P7: 2
C8: LYON OU | D8: 180 | E8: 172 | F8: 28 | G8: 7 | H8: 15 | I8: 24 | J8: 17 | K8: 32 | L8: 53 | M8: 0 | N8: 4 | O8: 15 | P8: 2
C9: MONTPELLIER HERAULT | D9: 180 | E9: 153 | F9: 22 | G9: 5 | H9: 10 | I9: 35 | J9: 10 | K9: 42 | L9: 51 | M9: 0 | N9: 5 | O9: 9 | P9: 2
C10: RACING 92 | D10: 154 | E10: 172 | F10: 22 | G10: 3 | H10: 13 | I10: 21 | J10: 13 | K10: 29 | L10: 52 | M10: 0 | N10: 1 | O10: 11 | P10: 0
C11: SECTION PALOISE | D11: 161 | E11: 180 | F11: 20 | G11: 4 | H11: 18 | I11: 22 | J11: 19 | K11: 27 | L11: 46 | M11: 0 | N11: 5 | O11: 13 | P11: 2
C12: STADE FRANCAIS | D12: 185 | E12: 171 | F12: 27 | G12: 7 | H12: 27 | I12: 24 | J12: 10 | K12: 33 | L12: 54 | M12: 0 | N12: 3 | O12: 17 | P12: 0
C13: TOULON | D13: 150 | E13: 202 | F13: 30 | G13: 3 | H13: 10 | I13: 24 | J13: 11 | K13: 20 | L13: 50 | M13: 0 | N13: 2 | O13: 13 | P13: 1
... C15: UNION BORDEAUX | D15: 171 | E15: 163 | F15: 39 | G15: 2 | H15: 7 | I15: 16 | J15: 19 | K15: 28 | L15: 57 | M15: 0 | N15: 3 | O15: 12 | P15: 1

Sheet Joueurs
B2: Joueur | C2: Equipe | D2: Matchs | E2: Minutes Jouées | F2: Essais | G2: Courses | H2: Mètres Parcourus | I2: Percussions | J2: Franchissements | K2: Plaquages Cassés | L2: Passes | M2: Offloads | N2: Turnover | O2: Plaquages Réussis | P2: Plaquages Offensifs | Q2: Plaquages Manqués | R2: Contest Ruck | S2: Ballons Grattés | T2: Rucks Offensifs | U2: Rucks Défensifs | V2: Pénalités Concédées | W2: Jeu au Pied | X2: Mètres au Pied | Y2: Prises en Touche | Z2: Touches Volées
B3: ADRIAN MOTOC | C3: AGEN | D3: 10 | E3: 230 | F3: 0 | G3: 21 | H3: 101 | I3: 21 | J3: 1 | K3: 0 | L3: 5 | M3: 0 | N3: 3 | O3: 59 | P3: 6 | Q3: 7 | R3: 7 | S3: 0 | T3: 40 | U3: 8 | V3: 3 | W3: 0 | X3: 0 | Y3: 7 | Z3: 0
B4: ANDRES ZAFRA TARAZONA | C4: AGEN | D4: 17 | E4: 1007 | F4: 3 | G4: 109 | H4: 371 | I4: 107 | J4: 0 | K4: 1 | L4: 49 | M4: 12 | N4: 8 | O4: 195 | P4: 30 | Q4: 29 | R4: 41 | S4: 2 | T4: 233 | U4: 49 | V4: 6 | W4: 0 | X4: 0 | Y4: 34 | Z4: 2
B5: ANTON PEIKRISHVILI | C5: AGEN | D5: 3 | E5: 86 | F5: 0 | G5: 3 | H5: 15 | I5: 3 | J5: 0 | K5: 0 | L5: 0 | M5: 0 | N5: 2 | O5: 19 | P5: 3 | Q5: 1 | R5: 4 | S5: 0 | T5: 17 | U5: 4 | V5: 4 | W5: 0 | X5: 0 | Y5: 0 | Z5: 0
B6: BENITO MASILEVU | C6: AGEN | D6: 8 | E6: 640 | F6: 2 | G6: 63 | H6: 507 | I6: 55 | J6: 4 | K6: 5 | L6: 20 | M6: 4 | N6: 13 | O6: 43 | P6: 10 | Q6: 9 | R6: 4 | S6: 0 | T6: 46 | U6: 4 | V6: 2 | W6: 3 | X6: 64 | Y6: 0 | Z6: 0
B7: CLEMENT MARTINEZ | C7: AGEN | D7: 12 | E7: 582 | F7: 0 | G7: 40 | H7: 173 | I7: 38 | J7: 1 | K7: 0 | L7: 17 | M7: 5 | N7: 12 | O7: 111 | P7: 9 | Q7: 5 | R7: 14 | S7: 1 | T7: 140 | U7: 17 | V7: 3 | W7: 0 | X7: 0 | Y7: 0 | Z7: 0
B8: CORENTIN CHABEAUDIE | C8: AGEN | D8: 1 | E8: 26 | F8: 0 | G8: 2 | H8: 5 | I8: 2 | J8: 0 | K8: 0 | L8: 1 | M8: 0 | N8: 0 | O8: 8 | P8: 0 | Q8: 0 | R8: 1 | S8: 0 | T8: 10 | U8: 1 | V8: 0 | W8: 0 | X8: 0 | Y8: 0 | Z8: 0
B9: DAVE RYAN | C9: AGEN | D9: 14 | E9: 719 | F9: 3 | G9: 58 | H9: 225 | I9: 57 | J9: 0 | K9: 0 | L9: 25 | M9: 1 | N9: 6 | O9: 118 | P9: 10 | Q9: 11 | R9: 23 | S9: 0 | T9: 181 | U9: 25 | V9: 8 | W9: 0 | X9: 0 | Y9: 0 | Z9: 0
B10: DYLAN HAYES | C10: AGEN | D10: 15 | E10: 690 | F10: 0 | G10: 46 | H10: 259 | I10: 45 | J10: 1 | K10: 2 | L10: 28 | M10: 2 | N10: 3 | O10: 111 | P10: 6 | Q10: 7 | R10: 25 | S10: 1 | T10: 134 | U10: 25 | V10: 2 | W10: 0 | X10: 0 | Y10: 5 | Z10: 1
B11: FERNANDEZ CORREA | C11: AGEN | D11: 2 | E11: 40 | F11: 0 | G11: 3 | H11: 9 | I11: 3 | J11: 0 | K11: 1 | L11: 1 | M11: 0 | N11: 1 | O11: 13 | P11: 1 | Q11: 3 | R11: 6 | S11: 0 | T11: 8 | U11: 6 | V11: 3 | W11: 0 | X11: 0 | Y11: 0 | Z11: 0
B12: GAUTHIER MARAVAT | C12: AGEN | D12: 4 | E12: 148 | F12: 0 | G12: 10 | H12: 52 | I12: 10 | J12: 1 | K12: 0 | L12: 1 | M12: 0 | N12: 2 | O12: 19 | P12: 3 | Q12: 3 | R12: 3 | S12: 0 | T12: 29 | U12: 3 | V12: 2 | W12: 0 | X12: 0 | Y12: 6 | Z12: 3
B13: GIORGI TETRASHVILI | C13: AGEN | D13: 14 | E13: 665 | F13: 0 | G13: 58 | H13: 196 | I13: 58 | J13: 0 | K13: 0 | L13: 13 | M13: 3 | N13: 4 | O13: 93 | P13: 6 | Q13: 5 | R13: 18 | S13: 1 | T13: 135 | U13: 17 | V13: 20 | W13: 0 | X13: 0 | Y13: 0 | Z13: 0
B14: HUGO VERDU | C14: AGEN | D14: 11 | E14: 388 | F14: 0 | G14: 15 | H14: 23 | I14: 10 | J14: 1 | K14: 2 | L14: 297 | M14: 4 | N14: 3 | O14: 32 | P14: 1 | Q14: 13 | R14: 1 | S14: 0 | T14: 13 | U14: 1 | V14: 2 | W14: 40 | X14: 811 | Y14: 0 | Z14: 0
... B586: ZAKARIA EL FAKIR | C586: UNION BORDEAUX | D586: 1 | E586: 18 | F586: 0 | G586: 1 | H586: 5 | I586: 1 | J586: 0 | K586: 0 | L586: 0 | M586: 0 | N586: 0 | O586: 3 | P586: 0 | Q586: 1 | R586: 0 | S586: 0 | T586: 8 | U586: 0 | V586: 0 | W586: 0 | X586: 0 | Y586: 0 | Z586: 0
B589: =IF(B590>0,"*"&B590&" joueurs additionnels avec moins de temps de jeu non affichés","")

Sheet Top joueurs points
A1: CLASSEMENT | B1: JOUEUR | C1: JOUEUR old | D1: Valeur
A2: 1 | B2: =UPPER(_xlfn.TEXTBEFORE(C2," (")) -> THOMAS LARANJEIRA | C2: Thomas Laranjeira (Brive) | D2: 181
A3: 2 | B3: =UPPER(_xlfn.TEXTBEFORE(C3," (")) -> ANTHONY BELLEAU | C3: Anthony Belleau (Toulon) | D3: 171
A4: 3 | B4: =UPPER(_xlfn.TEXTBEFORE(C4," (")) -> ANTOINE HASTOY | C4: Antoine Hastoy (Section Paloise) | D4: 139
A5: 4 | B5: =UPPER(_xlfn.TEXTBEFORE(C5," (")) -> TEDDY IRIBAREN | C5: Teddy Iribaren (Racing 92) | D5: 126
A6: 5 | B6: =UPPER(_xlfn.TEXTBEFORE(C6," (")) -> JULIEN DUMORA | C6: Julien Dumora (Castres Olympique) | D6: 123
A7: 6 | B7: =UPPER(_xlfn.TEXTBEFORE(C7," (")) -> JONATHAN WISNIEWSKI | C7: Jonathan Wisniewski (Lyon OU) | D7: 122
A8: 7 | B8: =UPPER(_xlfn.TEXTBEFORE(C8," (")) -> JAKE MCINTYRE | C8: Jake McIntyre (ASM Clermont) | D8: 109
A9: 8 | B9: =UPPER(_xlfn.TEXTBEFORE(C9," (")) -> BEN BOTICA | C9: Ben Botica (Union Bordeaux) | D9: 101
A10: 9 | B10: =UPPER(_xlfn.TEXTBEFORE(C10," (")) -> MATTHIEU JALIBERT | C10: Matthieu Jalibert (Union Bordeaux) | D10: 97
A11: 10 | B11: =UPPER(_xlfn.TEXTBEFORE(C11," (")) -> ZACK HOLMES | C11: Zack Holmes (Toulouse) | D11: 94
A12: 11 | B12: =UPPER(_xlfn.TEXTBEFORE(C12," (")) -> JULES PLISSON | C12: Jules Plisson (La Rochelle) | D12: 85
A13: 12 | B13: =UPPER(_xlfn.TEXTBEFORE(C13," (")) -> LEO BERDEU | C13: Leo Berdeu (Agen) | D13: 79
... A29: 28 | B29: =UPPER(_xlfn.TEXTBEFORE(C29," (")) -> JEAN-MARC DOUSSAIN | C29: Jean-Marc Doussain (Lyon OU) | D29: 44

Sheet Top joueurs tirs au but
A1: CLASSEMENT | B1: JOUEUR | C1: JOUEURcold | D1: TENTATIVE | E1: RÉUSSIS | F1: MANQUÉS | G1: PRÉCISION | H1: POINTS
A2: 1 | B2: =UPPER(_xlfn.TEXTBEFORE(C2," (")) -> BROCK JAMES | C2: Brock James (La Rochelle) | D2: 17 | E2: 16 | F2: 1 | G2: 0.94117647 | H2: 42
A3: 2 | B3: =UPPER(_xlfn.TEXTBEFORE(C3," (")) -> MORGAN PARRA | C3: Morgan Parra (ASM Clermont) | D3: 26 | E3: 24 | F3: 2 | G3: 0.92307692 | H3: 65
A4: 2 | B4: =UPPER(_xlfn.TEXTBEFORE(C4," (")) -> BENJAMIN URDAPILLETA | C4: Benjamin Urdapilleta (Castres Olympique) | D4: 13 | E4: 12 | F4: 1 | G4: 0.92307692 | H4: 29
A5: 4 | B5: =UPPER(_xlfn.TEXTBEFORE(C5," (")) -> THOMAS LARANJEIRA | C5: Thomas Laranjeira (Brive) | D5: 71 | E5: 64 | F5: 7 | G5: 0.90140845 | H5: 166
A6: 5 | B6: =UPPER(_xlfn.TEXTBEFORE(C6," (")) -> MORNE STEYN | C6: Morne Steyn (Stade Francais) | D6: 18 | E6: 16 | F6: 2 | G6: 0.88888889 | H6: 42
A7: 6 | B7: =UPPER(_xlfn.TEXTBEFORE(C7," (")) -> JONATHAN WISNIEWSKI | C7: Jonathan Wisniewski (Lyon OU) | D7: 53 | E7: 47 | F7: 6 | G7: 0.88679245 | H7: 119
A8: 7 | B8: =UPPER(_xlfn.TEXTBEFORE(C8," (")) -> ENZO HERVE | C8: Enzo Herve (Brive) | D8: 16 | E8: 14 | F8: 2 | G8: 0.875 | H8: 38
A9: 8 | B9: =UPPER(_xlfn.TEXTBEFORE(C9," (")) -> MAXIME LAFAGE | C9: Maxime Lafage (Aviron Bayonnais) | D9: 22 | E9: 19 | F9: 3 | G9: 0.86363636 | H9: 52
A10: 9 | B10: =UPPER(_xlfn.TEXTBEFORE(C10," (")) -> ANTHONY BELLEAU | C10: Anthony Belleau (Toulon) | D10: 76 | E10: 65 | F10: 11 | G10: 0.85526316 | H10: 171
A11: 10 | B11: =UPPER(_xlfn.TEXTBEFORE(C11," (")) -> JAKE MCINTYRE | C11: Jake McIntyre (ASM Clermont) | D11: 46 | E11: 39 | F11: 7 | G11: 0.84782609 | H11: 104
A12: 11 | B12: =UPPER(_xlfn.TEXTBEFORE(C12," (")) -> THOMAS RAMOS | C12: Thomas Ramos (Toulouse) | D12: 31 | E12: 26 | F12: 5 | G12: 0.83870968 | H12: 65
A13: 12 | B13: =UPPER(_xlfn.TEXTBEFORE(C13," (")) -> ANTOINE HASTOY | C13: Antoine Hastoy (Section Paloise) | D13: 60 | E13: 50 | F13: 10 | G13: 0.83333333 | H13: 134
... A29: 27 | B29: =UPPER(_xlfn.TEXTBEFORE(C29," (")) -> RORY KOCKOTT | C29: Rory Kockott (Castres Olympique) | D29: 26 | E29: 20 | F29: 6 | G29: 0.76923077 | H29: 54
A30: 29 | C30: Jean-Marc Doussain (Lyon OU) | D30: 21 | E30: 16 | F30: 5 | G30: 0.76190476 | H30: 39
A31: 30 | C31: Zack Holmes (Toulouse) | D31: 41 | E31: 31 | F31: 10 | G31: 0.75609756 | H31: 86
A32: 31 | C32: Teddy Iribaren (Racing 92) | D32: 64 | E32: 48 | F32: 16 | G32: 0.75 | H32: 121
A33: 32 | C33: Jules Plisson (La Rochelle) | D33: 42 | E33: 31 | F33: 11 | G33: 0.73809524 | H33: 80
A34: 33 | C34: Ihaia West (La Rochelle) | D34: 30 | E34: 22 | F34: 8 | G34: 0.73333333 | H34: 56
A35: 34 | C35: Romain Barthelemy (Aviron Bayonnais) | D35: 41 | E35: 28 | F35: 13 | G35: 0.68292683 | H35: 76
A36: 35 | C36: Nicolas Sanchez (Stade Francais) | D36: 34 | E36: 23 | F36: 11 | G36: 0.67647059 | H36: 63
A37: 35 | C37: Joris Segonds (Stade Francais) | D37: 34 | E37: 23 | F37: 11 | G37: 0.67647059 | H37: 61
A38: 37 | C38: Leo Berdeu (Agen) | D38: 43 | E38: 28 | F38: 15 | G38: 0.65116279 | H38: 71
A39: 38 | C39: Marc Palmier (ASM Clermont) | D39: 9 | E39: 4 | F39: 5 | G39: 0.44444444 | H39: 10
A40: - | C40: Thomas Vincent (Agen) | D40: 4 | E40: 4 | F40: 0 | G40: 1 | H40: 10
A41: - | C41: Romain Ntamack (Toulouse) | D41: 3 | E41: 3 | F41: 0 | G41: 1 | H41: 8
A42: - | C42: Henry Immelman (Montpellier Herault) | D42: 2 | E42: 2 | F42: 0 | G42: 1 | H42: 6
A43: - | C43: UJ Seuteni (Union Bordeaux) | D43: 3 | E43: 3 | F43: 0 | G43: 1 | H43: 6
A44: - | C44: Thomas Taylor (Section Paloise) | D44: 2 | E44: 2 | F44: 0 | G44: 1 | H44: 5
A45: - | C45: Joaquin Diaz Bonilla (Racing 92) | D45: 2 | E45: 2 | F45: 0 | G45: 1 | H45: 4
A46: - | C46: Ludovic Radosavljevic (Castres Olympique) | D46: 1 | E46: 1 | F46: 0 | G46: 1 | H46: 3
A47: - | C47: Camille Lopez (ASM Clermont) | D47: 1 | E47: 1 | F47: 0 | G47: 1 | H47: 2
A48: - | C48: Francois Trinh-Duc (Racing 92) | D48: 1 | E48: 1 | F48: 0 | G48: 1 | H48: 2
A49: - | C49: Mathieu Smaili (Toulon) | D49: 1 | E49: 1 | F49: 0 | G49: 1 | H49: 2
A50: - | C50: Charlie Ngatai (Lyon OU) | D50: 5 | E50: 4 | F50: 1 | G50: 0.8 | H50: 12
A51: - | C51: Cheslin Kolbe (Toulouse) | D51: 5 | E51: 4 | F51: 1 | G51: 0.8 | H51: 10
... A60: - | C60: Samuel Marques (Section Paloise) | D60: 2 | E60: 0 | F60: 2 | G60: 0 | H60: 0

Sheet Top joueurs essais 
A1: CLASSEMENT | B1: JOUEUR | C1: JOUEUR old | D1: Valeur
A2: 1 | B2: =UPPER(_xlfn.TEXTBEFORE(C2," (")) -> ARTHUR RETIERE | C2: Arthur Retiere (La Rochelle) | D2: 8
A3: 2 | B3: =UPPER(_xlfn.TEXTBEFORE(C3," (")) -> KYLAN HAMDAOUI | C3: Kylan Hamdaoui (Stade Francais) | D3: 7
A4: 2 | B4: =UPPER(_xlfn.TEXTBEFORE(C4," (")) -> NEMANI NADOLO | C4: Nemani Nadolo (Montpellier Herault) | D4: 7
A5: 2 | B5: =UPPER(_xlfn.TEXTBEFORE(C5," (")) -> THOMAS COMBEZOU | C5: Thomas Combezou (Castres Olympique) | D5: 7
A6: 5 | B6: =UPPER(_xlfn.TEXTBEFORE(C6," (")) -> JUAN IMHOFF | C6: Juan Imhoff (Racing 92) | D6: 6
A7: 5 | B7: =UPPER(_xlfn.TEXTBEFORE(C7," (")) -> SANTIAGO CORDERO | C7: Santiago Cordero (Union Bordeaux) | D7: 6
A8: 5 | B8: =UPPER(_xlfn.TEXTBEFORE(C8," (")) -> TEDDY THOMAS | C8: Teddy Thomas (Racing 92) | D8: 6
A9: 5 | B9: =UPPER(_xlfn.TEXTBEFORE(C9," (")) -> XAVIER MIGNOT | C9: Xavier Mignot (Lyon OU) | D9: 6
A10: 9 | B10: =UPPER(_xlfn.TEXTBEFORE(C10," (")) -> ANTHONY BOUTHIER | C10: Anthony Bouthier (Montpellier Herault) | D10: 5
A11: 9 | B11: =UPPER(_xlfn.TEXTBEFORE(C11," (")) -> DANIEL IKPEFAN | C11: Daniel Ikpefan (Toulon) | D11: 5
A12: 9 | B12: =UPPER(_xlfn.TEXTBEFORE(C12," (")) -> JOHANN SADIE | C12: Johann Sadie (Agen) | D12: 5
A13: 9 | B13: =UPPER(_xlfn.TEXTBEFORE(C13," (")) -> JORIS JURAND | C13: Joris Jurand (Brive) | D13: 5
... A29: 19 | B29: =UPPER(_xlfn.TEXTBEFORE(C29," (")) -> MATTHIS LEBEL | C29: Matthis Lebel (Toulouse) | D29: 4

Sheet Top joueurs plaquages réussis
A1: CLASSEMENT | B1: JOUEUR | C1: JOUEUR old | D1: Valeur
A2: 1 | B2: =UPPER(_xlfn.TEXTBEFORE(C2," (")) -> MARTIN PUECH | C2: Martin Puech (Section Paloise) | D2: 283
A3: 2 | B3: =UPPER(_xlfn.TEXTBEFORE(C3," (")) -> TOM MURDAY | C3: Tom Murday (Agen) | D3: 198
A4: 2 | B4: =UPPER(_xlfn.TEXTBEFORE(C4," (")) -> YOANN MAESTRI | C4: Yoann Maestri (Stade Francais) | D4: 198
A5: 4 | B5: =UPPER(_xlfn.TEXTBEFORE(C5," (")) -> FABRICE METZ | C5: Fabrice Metz (Section Paloise) | D5: 196
A6: 5 | B6: =UPPER(_xlfn.TEXTBEFORE(C6," (")) -> ANDRES ZAFRA TARAZONA | C6: Andres Zafra Tarazona (Agen) | D6: 195
A7: 6 | B7: =UPPER(_xlfn.TEXTBEFORE(C7," (")) -> ANTHONY JELONCH | C7: Anthony Jelonch (Castres Olympique) | D7: 192
A8: 7 | B8: =UPPER(_xlfn.TEXTBEFORE(C8," (")) -> RYNHARDT ELSTADT | C8: Rynhardt Elstadt (Toulouse) | D8: 187
A9: 8 | B9: =UPPER(_xlfn.TEXTBEFORE(C9," (")) -> RAPHAEL LAKAFIA | C9: Raphael Lakafia (Toulon) | D9: 184
A10: 8 | B10: =UPPER(_xlfn.TEXTBEFORE(C10," (")) -> SAID HIRECHE | C10: Said Hireche (Brive) | D10: 184
A11: 10 | B11: =UPPER(_xlfn.TEXTBEFORE(C11," (")) -> TEDDY BAUBIGNY | C11: Teddy Baubigny (Racing 92) | D11: 180
A12: 11 | B12: =UPPER(_xlfn.TEXTBEFORE(C12," (")) -> KELIAN GALLETIER | C12: Kelian Galletier (Montpellier Herault) | D12: 179
A13: 12 | B13: =UPPER(_xlfn.TEXTBEFORE(C13," (")) -> BAPTISTE DELAPORTE | C13: Baptiste Delaporte (Castres Olympique) | D13: 178
... A26: 25 | B26: =UPPER(_xlfn.TEXTBEFORE(C26," (")) -> KITIONE KAMIKAMICA | C26: Kitione Kamikamica (Brive) | D26: 148
B27: =UPPER(_xlfn.TEXTBEFORE(C27," (")) -> #N/A
B28: =UPPER(_xlfn.TEXTBEFORE(C28," (")) -> #N/A
B29: =UPPER(_xlfn.TEXTBEFORE(C29," (")) -> #N/A

Sheet Top joueurs plaquages offensifs
A1: CLASSEMENT | B1: JOUEUR | C1: JOUEUR old | D1: Valeur
A2: 1 | B2: =UPPER(_xlfn.TEXTBEFORE(C2," (")) -> YOANN MAESTRI | C2: Yoann Maestri (Stade Francais) | D2: 35
A3: 2 | B3: =UPPER(_xlfn.TEXTBEFORE(C3," (")) -> ANDRES ZAFRA TARAZONA | C3: Andres Zafra Tarazona (Agen) | D3: 30
A4: 3 | B4: =UPPER(_xlfn.TEXTBEFORE(C4," (")) -> FABRICE METZ | C4: Fabrice Metz (Section Paloise) | D4: 29
A5: 4 | B5: =UPPER(_xlfn.TEXTBEFORE(C5," (")) -> RAPHAEL LAKAFIA | C5: Raphael Lakafia (Toulon) | D5: 28
A6: 5 | B6: =UPPER(_xlfn.TEXTBEFORE(C6," (")) -> RYNHARDT ELSTADT | C6: Rynhardt Elstadt (Toulouse) | D6: 27
A7: 6 | B7: =UPPER(_xlfn.TEXTBEFORE(C7," (")) -> MARTIN PUECH | C7: Martin Puech (Section Paloise) | D7: 24
A8: 6 | B8: =UPPER(_xlfn.TEXTBEFORE(C8," (")) -> TALALELEI GRAY | C8: Talalelei Gray (Stade Francais) | D8: 24
A9: 8 | B9: =UPPER(_xlfn.TEXTBEFORE(C9," (")) -> LEKIMA TAGITAGIVALU | C9: Lekima Tagitagivalu (Section Paloise) | D9: 23
A10: 8 | B10: =UPPER(_xlfn.TEXTBEFORE(C10," (")) -> PAUL GABRILLAGUES | C10: Paul Gabrillagues (Stade Francais) | D10: 23
A11: 8 | B11: =UPPER(_xlfn.TEXTBEFORE(C11," (")) -> QUENTIN BETHUNE | C11: Quentin Bethune (Stade Francais) | D11: 23
A12: 8 | B12: =UPPER(_xlfn.TEXTBEFORE(C12," (")) -> SWAN REBBADJ | C12: Swan Rebbadj (Toulon) | D12: 23
A13: 12 | B13: =UPPER(_xlfn.TEXTBEFORE(C13," (")) -> RYAN CHAPUIS | C13: Ryan Chapuis (Stade Francais) | D13: 22
... A26: 21 | B26: =UPPER(_xlfn.TEXTBEFORE(C26," (")) -> KANE DOUGLAS | C26: Kane Douglas (Union Bordeaux) | D26: 18
B27: =UPPER(_xlfn.TEXTBEFORE(C27," (")) -> #N/A
B28: =UPPER(_xlfn.TEXTBEFORE(C28," (")) -> #N/A
B29: =UPPER(_xlfn.TEXTBEFORE(C29," (")) -> #N/A

Sheet Top joueurs jeu au pied
A1: CLASSEMENT | B1: JOUEUR | C1: JOUEUR old | D1: Valeur
A2: 1 | B2: =UPPER(_xlfn.TEXTBEFORE(C2," (")) -> RORY KOCKOTT | C2: Rory Kockott (Castres Olympique) | D2: 126
A3: 2 | B3: =UPPER(_xlfn.TEXTBEFORE(C3," (")) -> MAXIME LUCU | C3: Maxime Lucu (Union Bordeaux) | D3: 98
A4: 3 | B4: =UPPER(_xlfn.TEXTBEFORE(C4," (")) -> SEBASTIEN BEZY | C4: Sebastien Bezy (Toulouse) | D4: 95
A5: 4 | B5: =UPPER(_xlfn.TEXTBEFORE(C5," (")) -> ANTOINE HASTOY | C5: Antoine Hastoy (Section Paloise) | D5: 92
A6: 5 | B6: =UPPER(_xlfn.TEXTBEFORE(C6," (")) -> TEDDY IRIBAREN | C6: Teddy Iribaren (Racing 92) | D6: 89
A7: 6 | B7: =UPPER(_xlfn.TEXTBEFORE(C7," (")) -> JULIEN BLANC | C7: Julien Blanc (Brive) | D7: 85
A8: 7 | B8: =UPPER(_xlfn.TEXTBEFORE(C8," (")) -> PAUL ABADIE | C8: Paul Abadie (Agen) | D8: 82
A9: 8 | B9: =UPPER(_xlfn.TEXTBEFORE(C9," (")) -> CHARLIE NGATAI | C9: Charlie Ngatai (Lyon OU) | D9: 80
A10: 9 | B10: =UPPER(_xlfn.TEXTBEFORE(C10," (")) -> JONATHAN WISNIEWSKI | C10: Jonathan Wisniewski (Lyon OU) | D10: 78
A11: 10 | B11: =UPPER(_xlfn.TEXTBEFORE(C11," (")) -> ZACK HOLMES | C11: Zack Holmes (Toulouse) | D11: 77
A12: 11 | B12: =UPPER(_xlfn.TEXTBEFORE(C12," (")) -> MICHAEL RURU | C12: Michael Ruru (Aviron Bayonnais) | D12: 74
A13: 12 | B13: =UPPER(_xlfn.TEXTBEFORE(C13," (")) -> FINN RUSSELL | C13: Finn Russell (Racing 92) | D13: 73
... A26: 23 | B26: =UPPER(_xlfn.TEXTBEFORE(C26," (")) -> YANN LESGOURGUES | C26: Yann Lesgourgues (Union Bordeaux) | D26: 58
B27: =UPPER(_xlfn.TEXTBEFORE(C27," (")) -> #N/A
B28: =UPPER(_xlfn.TEXTBEFORE(C28," (")) -> #N/A
B29: =UPPER(_xlfn.TEXTBEFORE(C29," (")) -> #N/A

Sheet Top joueurs mètres parcourus
A1: CLASSEMENT | B1: JOUEUR | C1: JOUEUR old | D1: Valeur
A2: 1 | B2: =UPPER(_xlfn.TEXTBEFORE(C2," (")) -> JULIEN DUMORA | C2: Julien Dumora (Castres Olympique) | D2: 1167
A3: 2 | B3: =UPPER(_xlfn.TEXTBEFORE(C3," (")) -> BRICE DULIN | C3: Brice Dulin (Racing 92) | D3: 1114
A4: 3 | B4: =UPPER(_xlfn.TEXTBEFORE(C4," (")) -> KYLAN HAMDAOUI | C4: Kylan Hamdaoui (Stade Francais) | D4: 1101
A5: 4 | B5: =UPPER(_xlfn.TEXTBEFORE(C5," (")) -> GEORGE MOALA | C5: George Moala (ASM Clermont) | D5: 1085
A6: 5 | B6: =UPPER(_xlfn.TEXTBEFORE(C6," (")) -> THOMAS LARANJEIRA | C6: Thomas Laranjeira (Brive) | D6: 1075
A7: 6 | B7: =UPPER(_xlfn.TEXTBEFORE(C7," (")) -> ANTHONY BOUTHIER | C7: Anthony Bouthier (Montpellier Herault) | D7: 1040
A8: 7 | B8: =UPPER(_xlfn.TEXTBEFORE(C8," (")) -> CHARLY MALIE | C8: Charly Malie (Section Paloise) | D8: 1031
A9: 8 | B9: =UPPER(_xlfn.TEXTBEFORE(C9," (")) -> LAURENCE PEARCE | C9: Laurence Pearce (Agen) | D9: 989
A10: 9 | B10: =UPPER(_xlfn.TEXTBEFORE(C10," (")) -> JORIS JURAND | C10: Joris Jurand (Brive) | D10: 956
A11: 10 | B11: =UPPER(_xlfn.TEXTBEFORE(C11," (")) -> TOBY ARNOLD | C11: Toby Arnold (Lyon OU) | D11: 937
A12: 11 | B12: =UPPER(_xlfn.TEXTBEFORE(C12," (")) -> GERVAIS CORDIN | C12: Gervais Cordin (Toulon) | D12: 908
A13: 12 | B13: =UPPER(_xlfn.TEXTBEFORE(C13," (")) -> SOOTALA FA'ASO'O | C13: Sootala Fa'aso'o (Brive) | D13: 894
... A26: 25 | B26: =UPPER(_xlfn.TEXTBEFORE(C26," (")) -> ARTHUR RETIERE | C26: Arthur Retiere (La Rochelle) | D26: 743
B27: =UPPER(_xlfn.TEXTBEFORE(C27," (")) -> #N/A
B28: =UPPER(_xlfn.TEXTBEFORE(C28," (")) -> #N/A
B29: =UPPER(_xlfn.TEXTBEFORE(C29," (")) -> #N/A

Sheet Useless >>

Sheet Ruck & Maul
I2: RUCK & MAUL | N2: =#REF! -> #REF!
N3: =#REF! -> #REF!
C6: RUCK | H6: VITESSE - ATTAQUE | M6: VITESSE - DEFENSE | R6: MAUL
B7: TOTAL | C7: Rucks Gagnés % | D7: Rucks Perdus % | E7: Total Rucks | F7: Rucks Gagnés | G7: Rucks Perdus | H7: Rucks Off | I7: Vitesse Moyenne | J7: 0-3 Secs | K7: 3-6 Secs | L7: >6 Secs | M7: Rucks Déf | N7: Vitesse Moyenne | O7: 0-3 Secs | P7: 3-6 Secs | Q7: >6 Secs | R7: Mauls | S7: Mauls Gagnés | T7: Mauls Perdus
B8: FRENCH TOP 14 | C8: 0.96737415 | D8: 0.032625846 | E8: 19647 | F8: 19006 | G8: 641 | H8: 18157 | I8: 3.726772 | J8: 10395 | K8: 4842 | L8: 2920 | M8: 18157 | N8: 3.726772 | O8: 10395 | P8: 4842 | Q8: 2920 | R8: 1149 | S8: 979 | T8: 170
B9: AGEN | C9: 0.96806967 | D9: 0.031930334 | E9: 1378 | F9: 1334 | G9: 44 | H9: 1281 | I9: 3.5628415 | J9: 777 | K9: 307 | L9: 197 | M9: 1499 | N9: 3.5957305 | O9: 902 | P9: 374 | Q9: 223 | R9: 74 | S9: 62 | T9: 12
B10: ASM CLERMONT | C10: 0.96156486 | D10: 0.038435141 | E10: 1457 | F10: 1401 | G10: 56 | H10: 1324 | I10: 3.6767372 | J10: 791 | K10: 323 | L10: 210 | M10: 1093 | N10: 3.820677 | O10: 598 | P10: 318 | Q10: 177 | R10: 82 | S10: 73 | T10: 9
B11: AVIRON BAYONNAIS | C11: 0.96484111 | D11: 0.035158891 | E11: 1479 | F11: 1427 | G11: 52 | H11: 1361 | I11: 3.8611315 | J11: 766 | K11: 333 | L11: 262 | M11: 1328 | N11: 3.8125 | O11: 724 | P11: 381 | Q11: 223 | R11: 110 | S11: 94 | T11: 16
B12: BRIVE | C12: 0.96646796 | D12: 0.033532042 | E12: 1342 | F12: 1297 | G12: 45 | H12: 1250 | I12: 4.0912 | J12: 676 | K12: 355 | L12: 219 | M12: 1431 | N12: 3.2760307 | O12: 915 | P12: 350 | Q12: 166 | R12: 68 | S12: 53 | T12: 15
B13: CASTRES OLYMPIQUE | C13: 0.97205882 | D13: 0.027941176 | E13: 1360 | F13: 1322 | G13: 38 | H13: 1267 | I13: 4.0947119 | J13: 652 | K13: 383 | L13: 232 | M13: 1356 | N13: 3.5457227 | O13: 815 | P13: 340 | Q13: 201 | R13: 72 | S13: 62 | T13: 10
B14: LA ROCHELLE | C14: 0.97140815 | D14: 0.028591851 | E14: 1399 | F14: 1359 | G14: 40 | H14: 1294 | I14: 3.4629057 | J14: 741 | K14: 382 | L14: 171 | M14: 1130 | N14: 3.9256637 | O14: 630 | P14: 283 | Q14: 217 | R14: 58 | S14: 49 | T14: 9
B15: LYON OU | C15: 0.97113249 | D15: 0.028867506 | E15: 1351 | F15: 1312 | G15: 39 | H15: 1254 | I15: 3.7089314 | J15: 707 | K15: 330 | L15: 217 | M15: 1228 | N15: 3.9210098 | O15: 663 | P15: 358 | Q15: 207 | R15: 74 | S15: 70 | T15: 4
B16: MONTPELLIER HERAULT | C16: 0.9630485 | D16: 0.036951501 | E16: 1299 | F16: 1251 | G16: 48 | H16: 1200 | I16: 3.4575 | J16: 726 | K16: 304 | L16: 170 | M16: 1259 | N16: 3.6743447 | O16: 736 | P16: 334 | Q16: 189 | R16: 90 | S16: 76 | T16: 14
B17: RACING 92 | C17: 0.97046703 | D17: 0.029532967 | E17: 1456 | F17: 1413 | G17: 43 | H17: 1355 | I17: 3.3630996 | J17: 853 | K17: 344 | L17: 158 | M17: 1381 | N17: 3.7089066 | O17: 789 | P17: 376 | Q17: 216 | R17: 98 | S17: 83 | T17: 15
B18: SECTION PALOISE | C18: 0.96398166 | D18: 0.036018337 | E18: 1527 | F18: 1472 | G18: 55 | H18: 1401 | I18: 3.3675946 | J18: 885 | K18: 357 | L18: 159 | M18: 1372 | N18: 3.8695335 | O18: 751 | P18: 369 | Q18: 252 | R18: 86 | S18: 69 | T18: 17
B19: STADE FRANCAIS | C19: 0.965542 | D19: 0.034458004 | E19: 1393 | F19: 1345 | G19: 48 | H19: 1294 | I19: 3.797527 | J19: 741 | K19: 340 | L19: 213 | M19: 1278 | N19: 3.8732394 | O19: 675 | P19: 383 | Q19: 220 | R19: 61 | S19: 50 | T19: 11
... B22: UNION BORDEAUX | C22: 0.9688716 | D22: 0.031128405 | E22: 1542 | F22: 1494 | G22: 48 | H22: 1435 | I22: 4.0592334 | J22: 773 | K22: 361 | L22: 301 | M22: 1321 | N22: 3.7486752 | O22: 739 | P22: 367 | Q22: 215 | R22: 75 | S22: 65 | T22: 10
C28: RUCK | H28: VITESSE - ATTAQUE | M28: VITESSE - DEFENSE | R28: MAUL
B29: MOYENNE | C29: Rucks Gagnés % | D29: Rucks Perdus % | E29: Total Rucks | F29: Rucks Gagnés | G29: Rucks Perdus | H29: Rucks Off | I29: Vitesse Moyenne | J29: 0-3 Secs | K29: 3-6 Secs | L29: >6 Secs | M29: Rucks Déf | N29: Vitesse Moyenne | O29: 0-3 Secs | P29: 3-6 Secs | Q29: >6 Secs | R29: Mauls | S29: Mauls Gagnés | T29: Mauls Perdus
B30: FRENCH TOP 14 | C30: 0.96737415 | D30: 0.032625846 | E30: 82.55042 | F30: 79.857143 | G30: 2.6932773 | H30: 76.289916 | I30: 3.726772 | J30: 43.676471 | K30: 20.344538 | L30: 12.268908 | M30: 76.289916 | N30: 3.726772 | O30: 43.676471 | P30: 20.344538 | Q30: 12.268908 | R30: 4.8277311 | S30: 4.1134454 | T30: 0.71428571
B31: AGEN | C31: 0.96806967 | D31: 0.031930334 | E31: 81.058824 | F31: 78.470588 | G31: 2.5882353 | H31: 75.352941 | I31: 3.5628415 | J31: 45.705882 | K31: 18.058824 | L31: 11.588235 | M31: 88.176471 | N31: 3.5957305 | O31: 53.058824 | P31: 22 | Q31: 13.117647 | R31: 4.3529412 | S31: 3.6470588 | T31: 0.70588235
B32: ASM CLERMONT | C32: 0.96156486 | D32: 0.038435141 | E32: 85.705882 | F32: 82.411765 | G32: 3.2941176 | H32: 77.882353 | I32: 3.6767372 | J32: 46.529412 | K32: 19 | L32: 12.352941 | M32: 64.294118 | N32: 3.820677 | O32: 35.176471 | P32: 18.705882 | Q32: 10.411765 | R32: 4.8235294 | S32: 4.2941176 | T32: 0.52941176
B33: AVIRON BAYONNAIS | C33: 0.96484111 | D33: 0.035158891 | E33: 87 | F33: 83.941176 | G33: 3.0588235 | H33: 80.058824 | I33: 3.8611315 | J33: 45.058824 | K33: 19.588235 | L33: 15.411765 | M33: 78.117647 | N33: 3.8125 | O33: 42.588235 | P33: 22.411765 | Q33: 13.117647 | R33: 6.4705882 | S33: 5.5294118 | T33: 0.94117647
B34: BRIVE | C34: 0.96646796 | D34: 0.033532042 | E34: 78.941176 | F34: 76.294118 | G34: 2.6470588 | H34: 73.529412 | I34: 4.0912 | J34: 39.764706 | K34: 20.882353 | L34: 12.882353 | M34: 84.176471 | N34: 3.2760307 | O34: 53.823529 | P34: 20.588235 | Q34: 9.7647059 | R34: 4 | S34: 3.1176471 | T34: 0.88235294
B35: CASTRES OLYMPIQUE | C35: 0.97205882 | D35: 0.027941176 | E35: 80 | F35: 77.764706 | G35: 2.2352941 | H35: 74.529412 | I35: 4.0947119 | J35: 38.352941 | K35: 22.529412 | L35: 13.647059 | M35: 79.764706 | N35: 3.5457227 | O35: 47.941176 | P35: 20 | Q35: 11.823529 | R35: 4.2352941 | S35: 3.6470588 | T35: 0.58823529
B36: LA ROCHELLE | C36: 0.97140815 | D36: 0.028591851 | E36: 82.294118 | F36: 79.941176 | G36: 2.3529412 | H36: 76.117647 | I36: 3.4629057 | J36: 43.588235 | K36: 22.470588 | L36: 10.058824 | M36: 66.470588 | N36: 3.9256637 | O36: 37.058824 | P36: 16.647059 | Q36: 12.764706 | R36: 3.4117647 | S36: 2.8823529 | T36: 0.52941176
B37: LYON OU | C37: 0.97113249 | D37: 0.028867506 | E37: 79.470588 | F37: 77.176471 | G37: 2.2941176 | H37: 73.764706 | I37: 3.7089314 | J37: 41.588235 | K37: 19.411765 | L37: 12.764706 | M37: 72.235294 | N37: 3.9210098 | O37: 39 | P37: 21.058824 | Q37: 12.176471 | R37: 4.3529412 | S37: 4.1176471 | T37: 0.23529412
